{
 "cells": [
  {
   "cell_type": "code",
   "execution_count": 7,
   "id": "03e3fd57-d52b-4c07-971e-29bf7011ddad",
   "metadata": {},
   "outputs": [
    {
     "name": "stderr",
     "output_type": "stream",
     "text": [
      "<>:19: SyntaxWarning: invalid escape sequence '\\s'\n",
      "<>:19: SyntaxWarning: invalid escape sequence '\\s'\n",
      "C:\\Users\\alekh\\AppData\\Local\\Temp\\ipykernel_46580\\3001368605.py:19: SyntaxWarning: invalid escape sequence '\\s'\n",
      "  data['text'] = data['text'].apply((lambda x: re.sub('[^a-zA-z0-9\\s]', '', x)))\n",
      "C:\\Users\\alekh\\AppData\\Local\\Temp\\ipykernel_46580\\3001368605.py:22: FutureWarning: Series.__getitem__ treating keys as positions is deprecated. In a future version, integer keys will always be treated as labels (consistent with DataFrame behavior). To access a value by position, use `ser.iloc[pos]`\n",
      "  row[0] = row[0].replace('rt', ' ')\n",
      "C:\\Users\\alekh\\AppData\\Local\\Temp\\ipykernel_46580\\3001368605.py:22: FutureWarning: Series.__setitem__ treating keys as positions is deprecated. In a future version, integer keys will always be treated as labels (consistent with DataFrame behavior). To set a value by position, use `ser.iloc[pos] = value`\n",
      "  row[0] = row[0].replace('rt', ' ')\n",
      "C:\\Users\\alekh\\anaconda3\\Lib\\site-packages\\keras\\src\\layers\\core\\embedding.py:90: UserWarning: Argument `input_length` is deprecated. Just remove it.\n",
      "  warnings.warn(\n"
     ]
    },
    {
     "name": "stdout",
     "output_type": "stream",
     "text": [
      "291/291 - 38s - 130ms/step - accuracy: 0.6419 - loss: 0.8259\n",
      "144/144 - 4s - 29ms/step - accuracy: 0.6654 - loss: 0.7799\n"
     ]
    },
    {
     "name": "stderr",
     "output_type": "stream",
     "text": [
      "WARNING:absl:You are saving your model as an HDF5 file via `model.save()` or `keras.saving.save_model(model)`. This file format is considered legacy. We recommend using instead the native Keras format, e.g. `model.save('my_model.keras')` or `keras.saving.save_model(model, 'my_model.keras')`. \n"
     ]
    },
    {
     "name": "stdout",
     "output_type": "stream",
     "text": [
      "0.7798879146575928\n",
      "0.6653560400009155\n",
      "['loss', 'compile_metrics']\n"
     ]
    }
   ],
   "source": [
    "import pandas as pd # data processing, CSV file I/O (e.g. pd.read_csv)\n",
    "from tensorflow.keras.preprocessing.text import Tokenizer\n",
    "from keras.preprocessing.sequence import pad_sequences\n",
    "from keras.models import Sequential\n",
    "from keras.layers import Dense, Embedding, LSTM, SpatialDropout1D\n",
    "from matplotlib import pyplot\n",
    "from sklearn.model_selection import train_test_split\n",
    "from keras.utils import to_categorical\n",
    "import re\n",
    "from tensorflow.keras.models import load_model\n",
    "\n",
    "from sklearn.preprocessing import LabelEncoder\n",
    "\n",
    "data = pd.read_csv(r'C:\\Users\\alekh\\Downloads\\Data.csv')\n",
    "# Keeping only the neccessary columns\n",
    "data = data[['text','sentiment']]\n",
    "\n",
    "data['text'] = data['text'].apply(lambda x: x.lower())\n",
    "data['text'] = data['text'].apply((lambda x: re.sub('[^a-zA-z0-9\\s]', '', x)))\n",
    "\n",
    "for idx, row in data.iterrows():\n",
    "    row[0] = row[0].replace('rt', ' ')\n",
    "\n",
    "max_fatures = 2000\n",
    "tokenizer = Tokenizer(num_words=max_fatures, split=' ')\n",
    "tokenizer.fit_on_texts(data['text'].values)\n",
    "X = tokenizer.texts_to_sequences(data['text'].values)\n",
    "\n",
    "X = pad_sequences(X)\n",
    "\n",
    "embed_dim = 128\n",
    "lstm_out = 196\n",
    "def createmodel():\n",
    "    model = Sequential()\n",
    "    model.add(Embedding(max_fatures, embed_dim,input_length = X.shape[1]))\n",
    "    model.add(LSTM(lstm_out, dropout=0.2, recurrent_dropout=0.2))\n",
    "    model.add(Dense(3,activation='softmax'))\n",
    "    model.compile(loss = 'categorical_crossentropy', optimizer='adam',metrics = ['accuracy'])\n",
    "    return model\n",
    "# print(model.summary())\n",
    "\n",
    "labelencoder = LabelEncoder()\n",
    "integer_encoded = labelencoder.fit_transform(data['sentiment'])\n",
    "y = to_categorical(integer_encoded)\n",
    "X_train, X_test, Y_train, Y_test = train_test_split(X,y, test_size = 0.33, random_state = 42)\n",
    "\n",
    "batch_size = 32\n",
    "model = createmodel()\n",
    "model.fit(X_train, Y_train, epochs = 1, batch_size=batch_size, verbose = 2)\n",
    "score,acc = model.evaluate(X_test,Y_test,verbose=2,batch_size=batch_size)\n",
    "print(score)\n",
    "print(acc)\n",
    "print(model.metrics_names)\n",
    "model.save(\"final_model.h5\")\n"
   ]
  },
  {
   "cell_type": "code",
   "execution_count": 10,
   "id": "68936ce5-3dca-44cb-950a-7d0d7c260eea",
   "metadata": {},
   "outputs": [
    {
     "name": "stderr",
     "output_type": "stream",
     "text": [
      "WARNING:absl:Compiled the loaded model, but the compiled metrics have yet to be built. `model.compile_metrics` will be empty until you train or evaluate the model.\n"
     ]
    },
    {
     "name": "stdout",
     "output_type": "stream",
     "text": [
      "1/1 - 1s - 1s/step\n",
      "Predicted sentiment:  Positive\n",
      "Predicted probabilities:  [0.59244    0.14307295 0.26448706]\n"
     ]
    }
   ],
   "source": [
    "from keras.models import load_model\n",
    "import numpy as np\n",
    "\n",
    "loaded_model = load_model('final_model.h5')\n",
    "\n",
    "new_text = [\"A lot of good things are happening. We are respected again throughout the world, and that's a great thing.@realDonaldTrump\"]\n",
    "new_text = tokenizer.texts_to_sequences(new_text)\n",
    "new_text = pad_sequences(new_text, maxlen=X.shape[1], dtype='int32', value=0)\n",
    "sentiment_prob = loaded_model.predict(new_text, batch_size=1, verbose=2)[0]\n",
    "\n",
    "sentiment_classes = ['Positive', 'Neutral', 'Negative']\n",
    "sentiment_pred = sentiment_classes[np.argmax(sentiment_prob)]\n",
    "\n",
    "print(\"Predicted sentiment: \", sentiment_pred)\n",
    "print(\"Predicted probabilities: \", sentiment_prob)"
   ]
  },
  {
   "cell_type": "code",
   "execution_count": 44,
   "id": "2400f08b-8028-4dd6-af5d-245238533d35",
   "metadata": {},
   "outputs": [
    {
     "ename": "ValueError",
     "evalue": "\nAll the 12 fits failed.\nIt is very likely that your model is misconfigured.\nYou can try to debug the error by setting error_score='raise'.\n\nBelow are more details about the failures:\n--------------------------------------------------------------------------------\n1 fits failed with the following error:\nTraceback (most recent call last):\n  File \"C:\\Users\\alekh\\anaconda3\\Lib\\site-packages\\sklearn\\model_selection\\_validation.py\", line 895, in _fit_and_score\n    estimator.fit(X_train, y_train, **fit_params)\n  File \"C:\\Users\\alekh\\anaconda3\\Lib\\site-packages\\scikeras\\wrappers.py\", line 1501, in fit\n    super().fit(X=X, y=y, sample_weight=sample_weight, **kwargs)\n  File \"C:\\Users\\alekh\\anaconda3\\Lib\\site-packages\\scikeras\\wrappers.py\", line 770, in fit\n    self._fit(\n  File \"C:\\Users\\alekh\\anaconda3\\Lib\\site-packages\\scikeras\\wrappers.py\", line 936, in _fit\n    self._check_model_compatibility(y)\n  File \"C:\\Users\\alekh\\anaconda3\\Lib\\site-packages\\scikeras\\wrappers.py\", line 559, in _check_model_compatibility\n    if self.n_outputs_expected_ != len(self.model_.outputs):\n                                       ^^^^^^^^^^^^^^^^^^^\n  File \"C:\\Users\\alekh\\anaconda3\\Lib\\site-packages\\keras\\src\\models\\sequential.py\", line 300, in outputs\n    raise AttributeError(\nAttributeError: Sequential model 'sequential_5' has no defined outputs yet.\n\n--------------------------------------------------------------------------------\n7 fits failed with the following error:\nTraceback (most recent call last):\n  File \"C:\\Users\\alekh\\anaconda3\\Lib\\site-packages\\sklearn\\model_selection\\_validation.py\", line 895, in _fit_and_score\n    estimator.fit(X_train, y_train, **fit_params)\n  File \"C:\\Users\\alekh\\anaconda3\\Lib\\site-packages\\scikeras\\wrappers.py\", line 1501, in fit\n    super().fit(X=X, y=y, sample_weight=sample_weight, **kwargs)\n  File \"C:\\Users\\alekh\\anaconda3\\Lib\\site-packages\\scikeras\\wrappers.py\", line 770, in fit\n    self._fit(\n  File \"C:\\Users\\alekh\\anaconda3\\Lib\\site-packages\\scikeras\\wrappers.py\", line 936, in _fit\n    self._check_model_compatibility(y)\n  File \"C:\\Users\\alekh\\anaconda3\\Lib\\site-packages\\scikeras\\wrappers.py\", line 559, in _check_model_compatibility\n    if self.n_outputs_expected_ != len(self.model_.outputs):\n                                       ^^^^^^^^^^^^^^^^^^^\n  File \"C:\\Users\\alekh\\anaconda3\\Lib\\site-packages\\keras\\src\\models\\sequential.py\", line 300, in outputs\n    raise AttributeError(\nAttributeError: Sequential model 'sequential_1' has no defined outputs yet.\n\n--------------------------------------------------------------------------------\n3 fits failed with the following error:\nTraceback (most recent call last):\n  File \"C:\\Users\\alekh\\anaconda3\\Lib\\site-packages\\sklearn\\model_selection\\_validation.py\", line 895, in _fit_and_score\n    estimator.fit(X_train, y_train, **fit_params)\n  File \"C:\\Users\\alekh\\anaconda3\\Lib\\site-packages\\scikeras\\wrappers.py\", line 1501, in fit\n    super().fit(X=X, y=y, sample_weight=sample_weight, **kwargs)\n  File \"C:\\Users\\alekh\\anaconda3\\Lib\\site-packages\\scikeras\\wrappers.py\", line 770, in fit\n    self._fit(\n  File \"C:\\Users\\alekh\\anaconda3\\Lib\\site-packages\\scikeras\\wrappers.py\", line 936, in _fit\n    self._check_model_compatibility(y)\n  File \"C:\\Users\\alekh\\anaconda3\\Lib\\site-packages\\scikeras\\wrappers.py\", line 559, in _check_model_compatibility\n    if self.n_outputs_expected_ != len(self.model_.outputs):\n                                       ^^^^^^^^^^^^^^^^^^^\n  File \"C:\\Users\\alekh\\anaconda3\\Lib\\site-packages\\keras\\src\\models\\sequential.py\", line 300, in outputs\n    raise AttributeError(\nAttributeError: Sequential model 'sequential_2' has no defined outputs yet.\n\n--------------------------------------------------------------------------------\n1 fits failed with the following error:\nTraceback (most recent call last):\n  File \"C:\\Users\\alekh\\anaconda3\\Lib\\site-packages\\sklearn\\model_selection\\_validation.py\", line 895, in _fit_and_score\n    estimator.fit(X_train, y_train, **fit_params)\n  File \"C:\\Users\\alekh\\anaconda3\\Lib\\site-packages\\scikeras\\wrappers.py\", line 1501, in fit\n    super().fit(X=X, y=y, sample_weight=sample_weight, **kwargs)\n  File \"C:\\Users\\alekh\\anaconda3\\Lib\\site-packages\\scikeras\\wrappers.py\", line 770, in fit\n    self._fit(\n  File \"C:\\Users\\alekh\\anaconda3\\Lib\\site-packages\\scikeras\\wrappers.py\", line 936, in _fit\n    self._check_model_compatibility(y)\n  File \"C:\\Users\\alekh\\anaconda3\\Lib\\site-packages\\scikeras\\wrappers.py\", line 559, in _check_model_compatibility\n    if self.n_outputs_expected_ != len(self.model_.outputs):\n                                       ^^^^^^^^^^^^^^^^^^^\n  File \"C:\\Users\\alekh\\anaconda3\\Lib\\site-packages\\keras\\src\\models\\sequential.py\", line 300, in outputs\n    raise AttributeError(\nAttributeError: Sequential model 'sequential_6' has no defined outputs yet.\n",
     "output_type": "error",
     "traceback": [
      "\u001b[1;31m---------------------------------------------------------------------------\u001b[0m",
      "\u001b[1;31mValueError\u001b[0m                                Traceback (most recent call last)",
      "Cell \u001b[1;32mIn[44], line 25\u001b[0m\n\u001b[0;32m     23\u001b[0m \u001b[38;5;66;03m# Create GridSearchCV\u001b[39;00m\n\u001b[0;32m     24\u001b[0m grid \u001b[38;5;241m=\u001b[39m GridSearchCV(estimator\u001b[38;5;241m=\u001b[39mmodel, param_grid\u001b[38;5;241m=\u001b[39mparam_grid, n_jobs\u001b[38;5;241m=\u001b[39m\u001b[38;5;241m-\u001b[39m\u001b[38;5;241m1\u001b[39m, cv\u001b[38;5;241m=\u001b[39m\u001b[38;5;241m3\u001b[39m)\n\u001b[1;32m---> 25\u001b[0m grid_result \u001b[38;5;241m=\u001b[39m grid\u001b[38;5;241m.\u001b[39mfit(X_train, Y_train)\n\u001b[0;32m     27\u001b[0m \u001b[38;5;66;03m# Summarize results\u001b[39;00m\n\u001b[0;32m     28\u001b[0m \u001b[38;5;28mprint\u001b[39m(\u001b[38;5;124m\"\u001b[39m\u001b[38;5;124mBest: \u001b[39m\u001b[38;5;132;01m%f\u001b[39;00m\u001b[38;5;124m using \u001b[39m\u001b[38;5;132;01m%s\u001b[39;00m\u001b[38;5;124m\"\u001b[39m \u001b[38;5;241m%\u001b[39m (grid_result\u001b[38;5;241m.\u001b[39mbest_score_, grid_result\u001b[38;5;241m.\u001b[39mbest_params_))\n",
      "File \u001b[1;32m~\\anaconda3\\Lib\\site-packages\\sklearn\\base.py:1474\u001b[0m, in \u001b[0;36m_fit_context.<locals>.decorator.<locals>.wrapper\u001b[1;34m(estimator, *args, **kwargs)\u001b[0m\n\u001b[0;32m   1467\u001b[0m     estimator\u001b[38;5;241m.\u001b[39m_validate_params()\n\u001b[0;32m   1469\u001b[0m \u001b[38;5;28;01mwith\u001b[39;00m config_context(\n\u001b[0;32m   1470\u001b[0m     skip_parameter_validation\u001b[38;5;241m=\u001b[39m(\n\u001b[0;32m   1471\u001b[0m         prefer_skip_nested_validation \u001b[38;5;129;01mor\u001b[39;00m global_skip_validation\n\u001b[0;32m   1472\u001b[0m     )\n\u001b[0;32m   1473\u001b[0m ):\n\u001b[1;32m-> 1474\u001b[0m     \u001b[38;5;28;01mreturn\u001b[39;00m fit_method(estimator, \u001b[38;5;241m*\u001b[39margs, \u001b[38;5;241m*\u001b[39m\u001b[38;5;241m*\u001b[39mkwargs)\n",
      "File \u001b[1;32m~\\anaconda3\\Lib\\site-packages\\sklearn\\model_selection\\_search.py:970\u001b[0m, in \u001b[0;36mBaseSearchCV.fit\u001b[1;34m(self, X, y, **params)\u001b[0m\n\u001b[0;32m    964\u001b[0m     results \u001b[38;5;241m=\u001b[39m \u001b[38;5;28mself\u001b[39m\u001b[38;5;241m.\u001b[39m_format_results(\n\u001b[0;32m    965\u001b[0m         all_candidate_params, n_splits, all_out, all_more_results\n\u001b[0;32m    966\u001b[0m     )\n\u001b[0;32m    968\u001b[0m     \u001b[38;5;28;01mreturn\u001b[39;00m results\n\u001b[1;32m--> 970\u001b[0m \u001b[38;5;28mself\u001b[39m\u001b[38;5;241m.\u001b[39m_run_search(evaluate_candidates)\n\u001b[0;32m    972\u001b[0m \u001b[38;5;66;03m# multimetric is determined here because in the case of a callable\u001b[39;00m\n\u001b[0;32m    973\u001b[0m \u001b[38;5;66;03m# self.scoring the return type is only known after calling\u001b[39;00m\n\u001b[0;32m    974\u001b[0m first_test_score \u001b[38;5;241m=\u001b[39m all_out[\u001b[38;5;241m0\u001b[39m][\u001b[38;5;124m\"\u001b[39m\u001b[38;5;124mtest_scores\u001b[39m\u001b[38;5;124m\"\u001b[39m]\n",
      "File \u001b[1;32m~\\anaconda3\\Lib\\site-packages\\sklearn\\model_selection\\_search.py:1527\u001b[0m, in \u001b[0;36mGridSearchCV._run_search\u001b[1;34m(self, evaluate_candidates)\u001b[0m\n\u001b[0;32m   1525\u001b[0m \u001b[38;5;28;01mdef\u001b[39;00m \u001b[38;5;21m_run_search\u001b[39m(\u001b[38;5;28mself\u001b[39m, evaluate_candidates):\n\u001b[0;32m   1526\u001b[0m \u001b[38;5;250m    \u001b[39m\u001b[38;5;124;03m\"\"\"Search all candidates in param_grid\"\"\"\u001b[39;00m\n\u001b[1;32m-> 1527\u001b[0m     evaluate_candidates(ParameterGrid(\u001b[38;5;28mself\u001b[39m\u001b[38;5;241m.\u001b[39mparam_grid))\n",
      "File \u001b[1;32m~\\anaconda3\\Lib\\site-packages\\sklearn\\model_selection\\_search.py:947\u001b[0m, in \u001b[0;36mBaseSearchCV.fit.<locals>.evaluate_candidates\u001b[1;34m(candidate_params, cv, more_results)\u001b[0m\n\u001b[0;32m    940\u001b[0m \u001b[38;5;28;01melif\u001b[39;00m \u001b[38;5;28mlen\u001b[39m(out) \u001b[38;5;241m!=\u001b[39m n_candidates \u001b[38;5;241m*\u001b[39m n_splits:\n\u001b[0;32m    941\u001b[0m     \u001b[38;5;28;01mraise\u001b[39;00m \u001b[38;5;167;01mValueError\u001b[39;00m(\n\u001b[0;32m    942\u001b[0m         \u001b[38;5;124m\"\u001b[39m\u001b[38;5;124mcv.split and cv.get_n_splits returned \u001b[39m\u001b[38;5;124m\"\u001b[39m\n\u001b[0;32m    943\u001b[0m         \u001b[38;5;124m\"\u001b[39m\u001b[38;5;124minconsistent results. Expected \u001b[39m\u001b[38;5;132;01m{}\u001b[39;00m\u001b[38;5;124m \u001b[39m\u001b[38;5;124m\"\u001b[39m\n\u001b[0;32m    944\u001b[0m         \u001b[38;5;124m\"\u001b[39m\u001b[38;5;124msplits, got \u001b[39m\u001b[38;5;132;01m{}\u001b[39;00m\u001b[38;5;124m\"\u001b[39m\u001b[38;5;241m.\u001b[39mformat(n_splits, \u001b[38;5;28mlen\u001b[39m(out) \u001b[38;5;241m/\u001b[39m\u001b[38;5;241m/\u001b[39m n_candidates)\n\u001b[0;32m    945\u001b[0m     )\n\u001b[1;32m--> 947\u001b[0m _warn_or_raise_about_fit_failures(out, \u001b[38;5;28mself\u001b[39m\u001b[38;5;241m.\u001b[39merror_score)\n\u001b[0;32m    949\u001b[0m \u001b[38;5;66;03m# For callable self.scoring, the return type is only know after\u001b[39;00m\n\u001b[0;32m    950\u001b[0m \u001b[38;5;66;03m# calling. If the return type is a dictionary, the error scores\u001b[39;00m\n\u001b[0;32m    951\u001b[0m \u001b[38;5;66;03m# can now be inserted with the correct key. The type checking\u001b[39;00m\n\u001b[0;32m    952\u001b[0m \u001b[38;5;66;03m# of out will be done in `_insert_error_scores`.\u001b[39;00m\n\u001b[0;32m    953\u001b[0m \u001b[38;5;28;01mif\u001b[39;00m \u001b[38;5;28mcallable\u001b[39m(\u001b[38;5;28mself\u001b[39m\u001b[38;5;241m.\u001b[39mscoring):\n",
      "File \u001b[1;32m~\\anaconda3\\Lib\\site-packages\\sklearn\\model_selection\\_validation.py:536\u001b[0m, in \u001b[0;36m_warn_or_raise_about_fit_failures\u001b[1;34m(results, error_score)\u001b[0m\n\u001b[0;32m    529\u001b[0m \u001b[38;5;28;01mif\u001b[39;00m num_failed_fits \u001b[38;5;241m==\u001b[39m num_fits:\n\u001b[0;32m    530\u001b[0m     all_fits_failed_message \u001b[38;5;241m=\u001b[39m (\n\u001b[0;32m    531\u001b[0m         \u001b[38;5;124mf\u001b[39m\u001b[38;5;124m\"\u001b[39m\u001b[38;5;130;01m\\n\u001b[39;00m\u001b[38;5;124mAll the \u001b[39m\u001b[38;5;132;01m{\u001b[39;00mnum_fits\u001b[38;5;132;01m}\u001b[39;00m\u001b[38;5;124m fits failed.\u001b[39m\u001b[38;5;130;01m\\n\u001b[39;00m\u001b[38;5;124m\"\u001b[39m\n\u001b[0;32m    532\u001b[0m         \u001b[38;5;124m\"\u001b[39m\u001b[38;5;124mIt is very likely that your model is misconfigured.\u001b[39m\u001b[38;5;130;01m\\n\u001b[39;00m\u001b[38;5;124m\"\u001b[39m\n\u001b[0;32m    533\u001b[0m         \u001b[38;5;124m\"\u001b[39m\u001b[38;5;124mYou can try to debug the error by setting error_score=\u001b[39m\u001b[38;5;124m'\u001b[39m\u001b[38;5;124mraise\u001b[39m\u001b[38;5;124m'\u001b[39m\u001b[38;5;124m.\u001b[39m\u001b[38;5;130;01m\\n\u001b[39;00m\u001b[38;5;130;01m\\n\u001b[39;00m\u001b[38;5;124m\"\u001b[39m\n\u001b[0;32m    534\u001b[0m         \u001b[38;5;124mf\u001b[39m\u001b[38;5;124m\"\u001b[39m\u001b[38;5;124mBelow are more details about the failures:\u001b[39m\u001b[38;5;130;01m\\n\u001b[39;00m\u001b[38;5;132;01m{\u001b[39;00mfit_errors_summary\u001b[38;5;132;01m}\u001b[39;00m\u001b[38;5;124m\"\u001b[39m\n\u001b[0;32m    535\u001b[0m     )\n\u001b[1;32m--> 536\u001b[0m     \u001b[38;5;28;01mraise\u001b[39;00m \u001b[38;5;167;01mValueError\u001b[39;00m(all_fits_failed_message)\n\u001b[0;32m    538\u001b[0m \u001b[38;5;28;01melse\u001b[39;00m:\n\u001b[0;32m    539\u001b[0m     some_fits_failed_message \u001b[38;5;241m=\u001b[39m (\n\u001b[0;32m    540\u001b[0m         \u001b[38;5;124mf\u001b[39m\u001b[38;5;124m\"\u001b[39m\u001b[38;5;130;01m\\n\u001b[39;00m\u001b[38;5;132;01m{\u001b[39;00mnum_failed_fits\u001b[38;5;132;01m}\u001b[39;00m\u001b[38;5;124m fits failed out of a total of \u001b[39m\u001b[38;5;132;01m{\u001b[39;00mnum_fits\u001b[38;5;132;01m}\u001b[39;00m\u001b[38;5;124m.\u001b[39m\u001b[38;5;130;01m\\n\u001b[39;00m\u001b[38;5;124m\"\u001b[39m\n\u001b[0;32m    541\u001b[0m         \u001b[38;5;124m\"\u001b[39m\u001b[38;5;124mThe score on these train-test partitions for these parameters\u001b[39m\u001b[38;5;124m\"\u001b[39m\n\u001b[1;32m   (...)\u001b[0m\n\u001b[0;32m    545\u001b[0m         \u001b[38;5;124mf\u001b[39m\u001b[38;5;124m\"\u001b[39m\u001b[38;5;124mBelow are more details about the failures:\u001b[39m\u001b[38;5;130;01m\\n\u001b[39;00m\u001b[38;5;132;01m{\u001b[39;00mfit_errors_summary\u001b[38;5;132;01m}\u001b[39;00m\u001b[38;5;124m\"\u001b[39m\n\u001b[0;32m    546\u001b[0m     )\n",
      "\u001b[1;31mValueError\u001b[0m: \nAll the 12 fits failed.\nIt is very likely that your model is misconfigured.\nYou can try to debug the error by setting error_score='raise'.\n\nBelow are more details about the failures:\n--------------------------------------------------------------------------------\n1 fits failed with the following error:\nTraceback (most recent call last):\n  File \"C:\\Users\\alekh\\anaconda3\\Lib\\site-packages\\sklearn\\model_selection\\_validation.py\", line 895, in _fit_and_score\n    estimator.fit(X_train, y_train, **fit_params)\n  File \"C:\\Users\\alekh\\anaconda3\\Lib\\site-packages\\scikeras\\wrappers.py\", line 1501, in fit\n    super().fit(X=X, y=y, sample_weight=sample_weight, **kwargs)\n  File \"C:\\Users\\alekh\\anaconda3\\Lib\\site-packages\\scikeras\\wrappers.py\", line 770, in fit\n    self._fit(\n  File \"C:\\Users\\alekh\\anaconda3\\Lib\\site-packages\\scikeras\\wrappers.py\", line 936, in _fit\n    self._check_model_compatibility(y)\n  File \"C:\\Users\\alekh\\anaconda3\\Lib\\site-packages\\scikeras\\wrappers.py\", line 559, in _check_model_compatibility\n    if self.n_outputs_expected_ != len(self.model_.outputs):\n                                       ^^^^^^^^^^^^^^^^^^^\n  File \"C:\\Users\\alekh\\anaconda3\\Lib\\site-packages\\keras\\src\\models\\sequential.py\", line 300, in outputs\n    raise AttributeError(\nAttributeError: Sequential model 'sequential_5' has no defined outputs yet.\n\n--------------------------------------------------------------------------------\n7 fits failed with the following error:\nTraceback (most recent call last):\n  File \"C:\\Users\\alekh\\anaconda3\\Lib\\site-packages\\sklearn\\model_selection\\_validation.py\", line 895, in _fit_and_score\n    estimator.fit(X_train, y_train, **fit_params)\n  File \"C:\\Users\\alekh\\anaconda3\\Lib\\site-packages\\scikeras\\wrappers.py\", line 1501, in fit\n    super().fit(X=X, y=y, sample_weight=sample_weight, **kwargs)\n  File \"C:\\Users\\alekh\\anaconda3\\Lib\\site-packages\\scikeras\\wrappers.py\", line 770, in fit\n    self._fit(\n  File \"C:\\Users\\alekh\\anaconda3\\Lib\\site-packages\\scikeras\\wrappers.py\", line 936, in _fit\n    self._check_model_compatibility(y)\n  File \"C:\\Users\\alekh\\anaconda3\\Lib\\site-packages\\scikeras\\wrappers.py\", line 559, in _check_model_compatibility\n    if self.n_outputs_expected_ != len(self.model_.outputs):\n                                       ^^^^^^^^^^^^^^^^^^^\n  File \"C:\\Users\\alekh\\anaconda3\\Lib\\site-packages\\keras\\src\\models\\sequential.py\", line 300, in outputs\n    raise AttributeError(\nAttributeError: Sequential model 'sequential_1' has no defined outputs yet.\n\n--------------------------------------------------------------------------------\n3 fits failed with the following error:\nTraceback (most recent call last):\n  File \"C:\\Users\\alekh\\anaconda3\\Lib\\site-packages\\sklearn\\model_selection\\_validation.py\", line 895, in _fit_and_score\n    estimator.fit(X_train, y_train, **fit_params)\n  File \"C:\\Users\\alekh\\anaconda3\\Lib\\site-packages\\scikeras\\wrappers.py\", line 1501, in fit\n    super().fit(X=X, y=y, sample_weight=sample_weight, **kwargs)\n  File \"C:\\Users\\alekh\\anaconda3\\Lib\\site-packages\\scikeras\\wrappers.py\", line 770, in fit\n    self._fit(\n  File \"C:\\Users\\alekh\\anaconda3\\Lib\\site-packages\\scikeras\\wrappers.py\", line 936, in _fit\n    self._check_model_compatibility(y)\n  File \"C:\\Users\\alekh\\anaconda3\\Lib\\site-packages\\scikeras\\wrappers.py\", line 559, in _check_model_compatibility\n    if self.n_outputs_expected_ != len(self.model_.outputs):\n                                       ^^^^^^^^^^^^^^^^^^^\n  File \"C:\\Users\\alekh\\anaconda3\\Lib\\site-packages\\keras\\src\\models\\sequential.py\", line 300, in outputs\n    raise AttributeError(\nAttributeError: Sequential model 'sequential_2' has no defined outputs yet.\n\n--------------------------------------------------------------------------------\n1 fits failed with the following error:\nTraceback (most recent call last):\n  File \"C:\\Users\\alekh\\anaconda3\\Lib\\site-packages\\sklearn\\model_selection\\_validation.py\", line 895, in _fit_and_score\n    estimator.fit(X_train, y_train, **fit_params)\n  File \"C:\\Users\\alekh\\anaconda3\\Lib\\site-packages\\scikeras\\wrappers.py\", line 1501, in fit\n    super().fit(X=X, y=y, sample_weight=sample_weight, **kwargs)\n  File \"C:\\Users\\alekh\\anaconda3\\Lib\\site-packages\\scikeras\\wrappers.py\", line 770, in fit\n    self._fit(\n  File \"C:\\Users\\alekh\\anaconda3\\Lib\\site-packages\\scikeras\\wrappers.py\", line 936, in _fit\n    self._check_model_compatibility(y)\n  File \"C:\\Users\\alekh\\anaconda3\\Lib\\site-packages\\scikeras\\wrappers.py\", line 559, in _check_model_compatibility\n    if self.n_outputs_expected_ != len(self.model_.outputs):\n                                       ^^^^^^^^^^^^^^^^^^^\n  File \"C:\\Users\\alekh\\anaconda3\\Lib\\site-packages\\keras\\src\\models\\sequential.py\", line 300, in outputs\n    raise AttributeError(\nAttributeError: Sequential model 'sequential_6' has no defined outputs yet.\n"
     ]
    }
   ],
   "source": [
    "from scikeras.wrappers import KerasClassifier\n",
    "from sklearn.model_selection import GridSearchCV\n",
    "from keras.layers import LSTM\n",
    "\n",
    "# Function to create the model, as it's required by KerasClassifier\n",
    "def create_model(lstm_out=196, dropout=0.2):\n",
    "    model = Sequential()\n",
    "    model.add(Embedding(max_fatures, embed_dim, input_length=X.shape[1]))\n",
    "    model.add(LSTM(lstm_out, recurrent_dropout=0.2))\n",
    "    model.add(Dense(3, activation='softmax'))\n",
    "    model.compile(loss='categorical_crossentropy', optimizer='adam', metrics=['accuracy'])\n",
    "    return model\n",
    "\n",
    "# Create the KerasClassifier\n",
    "model = KerasClassifier(build_fn=create_model, epochs=1, batch_size=batch_size, verbose=2)\n",
    "\n",
    "# Define the grid of parameters to search\n",
    "param_grid = {\n",
    "    'model__lstm_out': [196, 256],\n",
    "    'model__dropout': [0.2, 0.3]\n",
    "}\n",
    "\n",
    "# Create GridSearchCV\n",
    "grid = GridSearchCV(estimator=model, param_grid=param_grid, n_jobs=-1, cv=3)\n",
    "grid_result = grid.fit(X_train, Y_train)\n",
    "\n",
    "# Summarize results\n",
    "print(\"Best: %f using %s\" % (grid_result.best_score_, grid_result.best_params_))"
   ]
  },
  {
   "cell_type": "code",
   "execution_count": null,
   "id": "b5838d27-8956-49a1-9bde-600355a01358",
   "metadata": {},
   "outputs": [],
   "source": [
    "best_model = grid_result.best_estimator_\n",
    "loss, accuracy = best_model.model.evaluate(X_test, y_test, verbose=0)\n",
    "print('Test Accuracy: %.2f' % (accuracy*100))"
   ]
  },
  {
   "cell_type": "code",
   "execution_count": null,
   "id": "4ce6c487-0c32-4dfd-87a8-f0809b79e638",
   "metadata": {},
   "outputs": [],
   "source": []
  }
 ],
 "metadata": {
  "kernelspec": {
   "display_name": "Python 3 (ipykernel)",
   "language": "python",
   "name": "python3"
  },
  "language_info": {
   "codemirror_mode": {
    "name": "ipython",
    "version": 3
   },
   "file_extension": ".py",
   "mimetype": "text/x-python",
   "name": "python",
   "nbconvert_exporter": "python",
   "pygments_lexer": "ipython3",
   "version": "3.12.4"
  }
 },
 "nbformat": 4,
 "nbformat_minor": 5
}
